Traceback (most recent call last):
  File "/home/bitzer/SoftDev/Python/ScienceEnv/SE/lib/python3.9/site-packages/jupyter_cache/executors/utils.py", line 51, in single_nb_execution
    executenb(
  File "/home/bitzer/SoftDev/Python/ScienceEnv/SE/lib/python3.9/site-packages/nbclient/client.py", line 1117, in execute
    return NotebookClient(nb=nb, resources=resources, km=km, **kwargs).execute()
  File "/home/bitzer/SoftDev/Python/ScienceEnv/SE/lib/python3.9/site-packages/nbclient/util.py", line 78, in wrapped
    return just_run(coro(*args, **kwargs))
  File "/home/bitzer/SoftDev/Python/ScienceEnv/SE/lib/python3.9/site-packages/nbclient/util.py", line 57, in just_run
    return loop.run_until_complete(coro)
  File "/usr/lib/python3.9/asyncio/base_events.py", line 642, in run_until_complete
    return future.result()
  File "/home/bitzer/SoftDev/Python/ScienceEnv/SE/lib/python3.9/site-packages/nbclient/client.py", line 558, in async_execute
    await self.async_execute_cell(
  File "/home/bitzer/SoftDev/Python/ScienceEnv/SE/lib/python3.9/site-packages/nbclient/client.py", line 862, in async_execute_cell
    self._check_raise_for_error(cell, exec_reply)
  File "/home/bitzer/SoftDev/Python/ScienceEnv/SE/lib/python3.9/site-packages/nbclient/client.py", line 765, in _check_raise_for_error
    raise CellExecutionError.from_cell_and_msg(cell, exec_reply_content)
nbclient.exceptions.CellExecutionError: An error occurred while executing the following cell:
------------------
import matplotlib
import numpy
from matplotlib import pyplot
from myst_nb import glue

matplotlib.style.use('sv.mplstyle')


fig, ax_signal = pyplot.subplot(3, 1, 1)
signal = numpy.random.random_sample(36)*4 - 2
ax_signal.stem(range(36), signal, use_line_collection=True)
ax_signal.set(xlabel='Folgenkindex k ->', ylabel='Amplitude x[k]', title='Eingangssignal', xlim=[0, 35])

ax_window = pyplot.subplot(3, 1, 2)
window = numpy.concatenate([[0]*10, [1]*16, [0]*10])
ax_window.step(range(36), window, where='mid')
ax_window.set(xlabel='Folgenkindex k ->', ylabel='Amplitude x[k]', title='Rechteck-Fensterfunktion', xlim=[0, 35])

ax_filtered = pyplot.subplot(3, 1, 3)
filtered_signal = signal * window
ax_filtered.stem(range(36), filtered_signal, use_line_collection=True)
ax_filtered.set(xlabel='Folgenkindex k ->', ylabel='Amplitude x[k]', title='gefenstertes Signal', xlim=[0, 35])

glue("DFT_FensterMultiplikation", fig, display=False)
------------------

[0;31m---------------------------------------------------------------------------[0m
[0;31mTypeError[0m                                 Traceback (most recent call last)
[0;32m/tmp/ipykernel_153276/1274483493.py[0m in [0;36m<module>[0;34m[0m
[1;32m      7[0m [0;34m[0m[0m
[1;32m      8[0m [0;34m[0m[0m
[0;32m----> 9[0;31m [0mfig[0m[0;34m,[0m [0max_signal[0m [0;34m=[0m [0mpyplot[0m[0;34m.[0m[0msubplot[0m[0;34m([0m[0;36m3[0m[0;34m,[0m [0;36m1[0m[0;34m,[0m [0;36m1[0m[0;34m)[0m[0;34m[0m[0;34m[0m[0m
[0m[1;32m     10[0m [0msignal[0m [0;34m=[0m [0mnumpy[0m[0;34m.[0m[0mrandom[0m[0;34m.[0m[0mrandom_sample[0m[0;34m([0m[0;36m36[0m[0;34m)[0m[0;34m*[0m[0;36m4[0m [0;34m-[0m [0;36m2[0m[0;34m[0m[0;34m[0m[0m
[1;32m     11[0m [0max_signal[0m[0;34m.[0m[0mstem[0m[0;34m([0m[0mrange[0m[0;34m([0m[0;36m36[0m[0;34m)[0m[0;34m,[0m [0msignal[0m[0;34m,[0m [0muse_line_collection[0m[0;34m=[0m[0;32mTrue[0m[0;34m)[0m[0;34m[0m[0;34m[0m[0m

[0;31mTypeError[0m: cannot unpack non-iterable AxesSubplot object
TypeError: cannot unpack non-iterable AxesSubplot object

