Traceback (most recent call last):
  File "/home/bitzer/SoftDev/Python/ScienceEnv/SE/lib/python3.9/site-packages/jupyter_cache/executors/utils.py", line 51, in single_nb_execution
    executenb(
  File "/home/bitzer/SoftDev/Python/ScienceEnv/SE/lib/python3.9/site-packages/nbclient/client.py", line 1117, in execute
    return NotebookClient(nb=nb, resources=resources, km=km, **kwargs).execute()
  File "/home/bitzer/SoftDev/Python/ScienceEnv/SE/lib/python3.9/site-packages/nbclient/util.py", line 78, in wrapped
    return just_run(coro(*args, **kwargs))
  File "/home/bitzer/SoftDev/Python/ScienceEnv/SE/lib/python3.9/site-packages/nbclient/util.py", line 57, in just_run
    return loop.run_until_complete(coro)
  File "/usr/lib/python3.9/asyncio/base_events.py", line 642, in run_until_complete
    return future.result()
  File "/home/bitzer/SoftDev/Python/ScienceEnv/SE/lib/python3.9/site-packages/nbclient/client.py", line 558, in async_execute
    await self.async_execute_cell(
  File "/home/bitzer/SoftDev/Python/ScienceEnv/SE/lib/python3.9/site-packages/nbclient/client.py", line 862, in async_execute_cell
    self._check_raise_for_error(cell, exec_reply)
  File "/home/bitzer/SoftDev/Python/ScienceEnv/SE/lib/python3.9/site-packages/nbclient/client.py", line 765, in _check_raise_for_error
    raise CellExecutionError.from_cell_and_msg(cell, exec_reply_content)
nbclient.exceptions.CellExecutionError: An error occurred while executing the following cell:
------------------
import matplotlib
import numpy
from matplotlib import pyplot
from myst_nb import glue

matplotlib.style.use('sv.mplstyle')

index_kausal = numpy.linspace(-10, 10, 21)
amplitude_kausal = [0]*len(index_kausal)
mid_kausal = int(numpy.floor(len(index_kausal)/2))
for idx in range(len(index_kausal)-mid_kausal):
    amplitude_kausal[idx+mid_kausal] = 0.5**idx

fig, (ax_kausal, ax_nkausal) = pyplot.subplots(1, 2)
ax_kausal.stem(index_kausal, amplitude_kausal, use_line_collection=True)
ax_kausal.set(xlabel='Folgenkindex k ->', ylabel='Amplitude x(k)', title='kaulase Folge 0.5**(k)*gamma(k)', xlim=[-10, 10])

index_nkausal = numpy.linspace(-10, 10, 21)
amplitude_nkausal = [0]*len(index_nkausal)
mid_nkausal = int(numpy.floor(len(index_nkausal)/2))
for idx in range(len(index_nkausal)-mid_nkausal):
    amplitude_nkausal[idx] = -1 * 0.5**(-10+idx)

ax_nkausal.stem(index_nkausal, amplitude_nkausal, use_line_collection=True)
ax_nkausal.set(xlabel='Folgenkindex k ->', ylabel='Amplitude x(k)', title='nicht kausale Folge -0.5**(-k)*gamma(-k)', xlim=[-10, 10], ylim=[-50, 0])

glue("zFolgenPic", fig, display=False)
------------------

[0;31m---------------------------------------------------------------------------[0m
[0;31mModuleNotFoundError[0m                       Traceback (most recent call last)
[0;32m/tmp/ipykernel_150833/3814722735.py[0m in [0;36m<module>[0;34m[0m
[0;32m----> 1[0;31m [0;32mimport[0m [0mmatplotlib[0m[0;34m[0m[0;34m[0m[0m
[0m[1;32m      2[0m [0;32mimport[0m [0mnumpy[0m[0;34m[0m[0;34m[0m[0m
[1;32m      3[0m [0;32mfrom[0m [0mmatplotlib[0m [0;32mimport[0m [0mpyplot[0m[0;34m[0m[0;34m[0m[0m
[1;32m      4[0m [0;32mfrom[0m [0mmyst_nb[0m [0;32mimport[0m [0mglue[0m[0;34m[0m[0;34m[0m[0m
[1;32m      5[0m [0;34m[0m[0m

[0;31mModuleNotFoundError[0m: No module named 'matplotlib'
ModuleNotFoundError: No module named 'matplotlib'

